Workbook
Name BtuTable: SEDS_CONS_API!$A$1:$BK$307
Name BuildingList: 'Chart Controls'!$D$3:$D$6
Name DivisionList: 'Chart Controls'!$B$3:$B$12
Name EndUseList: 'Chart Controls'!$E$3:$E$22
Name ExpTable: SEDS_EXP_API!$A$1:$BK$307
Name FirstNEMSYrPlot: 'Year Selections'!$C$17
Name FuelList: 'Chart Controls'!$C$3:$C$10
Name LastHHStockYr: 'Year Selections'!$C$20
Name LastSEDSyr: 'Year Selections'!$C$11
Name NEMS_Internal_PriceYr: 'Year Selections'!$C$5
Name PivotData: SEDSDataPivots!$C$3:$G$54
Name Price_Base_yr: 'Year Selections'!$C$8
Name RECSYr: 'Year Selections'!$C$14
Name SelectedBuilding: 'Chart Controls'!$D$25
Name SelectedDivision: 'Chart Controls'!$B$25
Name SelectedEndUse: 'Chart Controls'!$E$25
Name SelectedFuel: 'Chart Controls'!$C$25
Name SourceDir: Menu!$D$4

Sheet Menu
B2: NEMS Residential Database
B4: Source for Files | D4: \\Nemsfs\k\output\aeo2026\cb2026\d021826b\p1
B5: RunDescription | D5: AEO2026 Reference Case
B6: RunID | D6: =IF(RIGHT(SourceDir,3)<>"\p1",MID(SourceDir,(FIND("|",SUBSTITUTE(SourceDir,"\","|",LEN(SourceDir)-LEN(SUBSTITUTE(SourceDir,"\",""))-1)))+1,((FIND("\",SourceDir,(FIND("|",SUBSTITUTE(SourceDir,"\","|",LEN(SourceDir)-LEN(SUBSTITUTE(SourceDir,"\",""))-1)))+1))-(FIND("|",SUBSTITUTE(SourceDir,"\","|",LEN(SourceDir)-LEN(SUBSTITUTE(SourceDir,"\",""))-1))))-1)&"."&RIGHT(SourceDir,8),MID(SourceDir,(FIND("|",SUBSTITUTE(SourceDir,"\","|",LEN(SourceDir)-LEN(SUBSTITUTE(SourceDir,"\",""))-2)))+1,((FIND("\",SourceDir,(FIND("|",SUBSTITUTE(SourceDir,"\","|",LEN(SourceDir)-LEN(SUBSTITUTE(SourceDir,"\",""))-2)))+1))-(FIND("|",SUBSTITUTE(SourceDir,"\","|",LEN(SourceDir)-LEN(SUBSTITUTE(SourceDir,"\",""))-2))))-1)&"."&MID(SourceDir,(FIND("|",SUBSTITUTE(SourceDir,"\","|",LEN(SourceDir)-LEN(SUBSTITUTE(SourceDir,"\",""))-1)))+1,((FIND("\",SourceDir,(FIND("|",SUBSTITUTE(SourceDir,"\","|",LEN(SourceDir)-LEN(SUBSTITUTE(SourceDir,"\",""))-1)))+1))-(FIND("|",SUBSTITUTE(SourceDir,"\","|",LEN(SourceDir)-LEN(SUBSTITUTE(SourceDir,"\",""))-1))))-1)) -> cb2026.d021826b
B7: Last Change | D7: Remove deprecated kerosene consumption; rename LPG fuel price as Propane

Sheet Summary Charts
B1: Summary Historical Data with NEMS Projections
B2: =Menu!D5 -> AEO2026 Reference Case
F3: Chart Selections: | I3: Census Division: | K3: ='Chart Data Staging'!C3 -> (All)
I4: Fuel: | K4: ='Chart Data Staging'!C4 -> Electricity
I5: Building: | K5: ='Chart Data Staging'!C5 -> (All)
I6: End Use: | K6: ='Chart Data Staging'!C6 -> (All)
B8: Selections are possible for which some of the chart variables are not defined. Rather than generating an error, the affected charts will display blank or zero data.

Sheet Chart Data Staging
B2: Selections:
B3: Division | C3: =[0]!SelectedDivision -> (All) | E3: =IF(C3="(all)",0,1) -> 0
B4: Fuel | C4: =[0]!SelectedFuel -> Electricity | E4: =IF(C4="(all)",0,1) -> 1
B5: Building | C5: =[0]!SelectedBuilding -> (All) | E5: =IF(C5="(all)",0,1) -> 0
B6: End Use | C6: =[0]!SelectedEndUse -> (All) | E6: =IF(C6="(all)",0,1) -> 0
B8: Deflator Base Year | D8: =Price_Base_yr -> 2023
B9: Price Conversion Factor | D9: =HLOOKUP(D8,Deflators!$D$2:$BG$5,3,0) -> 2.3034306
B11: Availability
B12: Division | C12: 1 | G12: 1
B13: Fuel | C13: 1 | G13: 1
B14: Building | C14: 0 | G14: 0
B15: EndUse | C15: 0 | G15: 0
B16: Plot? | C16: 1 | G16: =SUMPRODUCT(G12:G15,$E$3:$E$6)-SUM($E$3:$E$6)+1 -> 1
G19: Historical | H19: Projected | J19: Historical | K19: Projected | M19: Historical | N19: Projected | P19: Historical | Q19: Projected | S19: Historical | T19: Projected | V19: Historical | W19: Projected
C20: Historical | E20: Projected | G20: Consumption | H20: Consumption | J20: Stocks | K20: Housing Stock | M20: Floorspace | N20: Floorspace | P20: Intensity | Q20: Intensity | S20: Intensity | T20: Intensity | V20: Avg | W20: Avg
C21: Prices | E21: Prices | G21: Quad | H21: Quad | J21: mill units | K21: mill units | M21: bill sqft | N21: bill sqft | P21: MMBtu/HH | Q21: MMBtu/HH | S21: MMBtu/1000sqft | T21: MMBtu/1000sqft | V21: Sqft | W21: Sqft
B22: =SEDSDataPivots!B8 -> 1970 | C22: =IF($D22>LastSEDSyr,#N/A,SEDSDataPivots!I8) -> #N/A | D22: =B23-1 -> 1970 | G22: =IF(G$16<1,#N/A,IF($D22>LastSEDSyr,#N/A,SEDSDataPivots!D8))/10^6 -> 0
B23: =B22+1 -> 1971 | C23: =IF($D23>LastSEDSyr,#N/A,SEDSDataPivots!I9) -> #VALUE! | D23: =D22+1 -> 1971 | G23: =IF(G$16<1,#N/A,IF($D23>LastSEDSyr,#N/A,SEDSDataPivots!D9))/10^6 -> 0.001798
B24: =B23+1 -> 1972 | C24: =IF($D24>LastSEDSyr,#N/A,SEDSDataPivots!I10) -> #VALUE! | D24: =D23+1 -> 1972 | G24: =IF(G$16<1,#N/A,IF($D24>LastSEDSyr,#N/A,SEDSDataPivots!D10))/10^6 -> 0.00415
B25: =B24+1 -> 1973 | C25: =IF($D25>LastSEDSyr,#N/A,SEDSDataPivots!I11) -> #VALUE! | D25: =D24+1 -> 1973 | G25: =IF(G$16<1,#N/A,IF($D25>LastSEDSyr,#N/A,SEDSDataPivots!D11))/10^6 -> 0.002832
B26: =B25+1 -> 1974 | C26: =IF($D26>LastSEDSyr,#N/A,SEDSDataPivots!I12) -> #VALUE! | D26: =D25+1 -> 1974 | G26: =IF(G$16<1,#N/A,IF($D26>LastSEDSyr,#N/A,SEDSDataPivots!D12))/10^6 -> 0.004384
B27: =B26+1 -> 1975 | C27: =IF($D27>LastSEDSyr,#N/A,SEDSDataPivots!I13) -> #VALUE! | D27: =D26+1 -> 1975 | G27: =IF(G$16<1,#N/A,IF($D27>LastSEDSyr,#N/A,SEDSDataPivots!D13))/10^6 -> 0.002059
B28: =B27+1 -> 1976 | C28: =IF($D28>LastSEDSyr,#N/A,SEDSDataPivots!I14) -> #VALUE! | D28: =D27+1 -> 1976 | G28: =IF(G$16<1,#N/A,IF($D28>LastSEDSyr,#N/A,SEDSDataPivots!D14))/10^6 -> 0.004742
B29: =B28+1 -> 1977 | C29: =IF($D29>LastSEDSyr,#N/A,SEDSDataPivots!I15) -> #VALUE! | D29: =D28+1 -> 1977 | G29: =IF(G$16<1,#N/A,IF($D29>LastSEDSyr,#N/A,SEDSDataPivots!D15))/10^6 -> 0.005037
B30: =B29+1 -> 1978 | C30: =IF($D30>LastSEDSyr,#N/A,SEDSDataPivots!I16) -> #VALUE! | D30: =D29+1 -> 1978 | G30: =IF(G$16<1,#N/A,IF($D30>LastSEDSyr,#N/A,SEDSDataPivots!D16))/10^6 -> 0.005878
B31: =B30+1 -> 1979 | C31: =IF($D31>LastSEDSyr,#N/A,SEDSDataPivots!I17) -> #VALUE! | D31: =D30+1 -> 1979 | G31: =IF(G$16<1,#N/A,IF($D31>LastSEDSyr,#N/A,SEDSDataPivots!D17))/10^6 -> 0.003988
B32: =B31+1 -> 1980 | C32: =IF($D32>LastSEDSyr,#N/A,SEDSDataPivots!I18) -> #VALUE! | D32: =D31+1 -> 1980 | G32: =IF(G$16<1,#N/A,IF($D32>LastSEDSyr,#N/A,SEDSDataPivots!D18))/10^6 -> 0.004775
B33: =B32+1 -> 1981 | C33: =IF($D33>LastSEDSyr,#N/A,SEDSDataPivots!I19) -> #VALUE! | D33: =D32+1 -> 1981 | G33: =IF(G$16<1,#N/A,IF($D33>LastSEDSyr,#N/A,SEDSDataPivots!D19))/10^6 -> 0.005411
B34: =B33+1 -> 1982 | C34: =IF($D34>LastSEDSyr,#N/A,SEDSDataPivots!I20) -> #VALUE! | D34: =D33+1 -> 1982 | G34: =IF(G$16<1,#N/A,IF($D34>LastSEDSyr,#N/A,SEDSDataPivots!D20))/10^6 -> 0.005234
... B41: =B40+1 -> 1989 | C41: =IF($D41>LastSEDSyr,#N/A,SEDSDataPivots!I27) -> #VALUE! | D41: =D40+1 -> 1989 | G41: =IF(G$16<1,#N/A,IF($D41>LastSEDSyr,#N/A,SEDSDataPivots!D27))/10^6 -> 0.006788
B42: =B41+1 -> 1990 | C42: =IF($D42>LastSEDSyr,#N/A,SEDSDataPivots!I28) -> #VALUE! | D42: =D41+1 -> 1990 | E42: =IF($E$4=0,#N/A,IF(B42>=FirstNEMSYrPlot,GETPIVOTDATA("EQSTOCK",NEMSPriceFcast!$A$7,"YEAR",B42)*$D$9,#N/A)) -> #N/A | G42: =IF(G$16<1,#N/A,IF($D42>LastSEDSyr,#N/A,SEDSDataPivots!D28))/10^6 -> 0.018247 | H42: =IF(B42>=FirstNEMSYrPlot,GETPIVOTDATA("CONSUMPTION",NEMSConsFcast!$A$9,"YEAR",B42)/10^9,#N/A) -> #N/A | J42: =IFERROR(IF(GETPIVOTDATA("Sum of "&D42,'RECS Data'!$B$99)=0,#N/A,GETPIVOTDATA("Sum of "&D42,'RECS Data'!$B$99)),#N/A) -> 93.990964 | K42: =IF($B42>RECSYr,GETPIVOTDATA("HOUSEHOLDS",HousingStockTable!$A$12,"YEAR",B42)/10^6,#N/A) -> #N/A | M42: =IFERROR(IF(AND(B42<=RECSYr,GETPIVOTDATA("Sum of "&B42,'RECS Data'!$B$179)>0),GETPIVOTDATA("Sum of "&B42,'RECS Data'!$B$179),#N/A)/1000,#N/A) -> 147.49028 | N42: =IF($B42>RECSYr,GETPIVOTDATA("HOUSEHOLDS",SqftTable!$A$7,"YEAR",B42),#N/A)/1000 -> #N/A | P42: =IF(ISERROR(G42/J42*1000),#N/A,G42/J42*1000) -> 0.19413568 | Q42: =H42/K42*1000 -> #N/A | S42: =IFERROR(G42/M42*10^3,#N/A) -> 0.12371663 | T42: =H42/N42*1000 -> #N/A | V42: =IFERROR(M42*1000/J42,#N/A) -> 1569.1964 | W42: =N42*1000/K42 -> #N/A
B43: =B42+1 -> 1991 | C43: =IF($D43>LastSEDSyr,#N/A,SEDSDataPivots!I29) -> #VALUE! | D43: =D42+1 -> 1991 | E43: =IF($E$4=0,#N/A,IF(B43>=FirstNEMSYrPlot,GETPIVOTDATA("EQSTOCK",NEMSPriceFcast!$A$7,"YEAR",B43)*$D$9,#N/A)) -> #N/A | G43: =IF(G$16<1,#N/A,IF($D43>LastSEDSyr,#N/A,SEDSDataPivots!D29))/10^6 -> 0.022109 | H43: =IF(B43>=FirstNEMSYrPlot,GETPIVOTDATA("CONSUMPTION",NEMSConsFcast!$A$9,"YEAR",B43)/10^9,#N/A) -> #N/A | J43: =IFERROR(IF(GETPIVOTDATA("Sum of "&D43,'RECS Data'!$B$99)=0,#N/A,GETPIVOTDATA("Sum of "&D43,'RECS Data'!$B$99)),#N/A) -> #N/A | K43: =IF($B43>RECSYr,GETPIVOTDATA("HOUSEHOLDS",HousingStockTable!$A$12,"YEAR",B43)/10^6,#N/A) -> #N/A | M43: =IFERROR(IF(AND(B43<=RECSYr,GETPIVOTDATA("Sum of "&B43,'RECS Data'!$B$179)>0),GETPIVOTDATA("Sum of "&B43,'RECS Data'!$B$179),#N/A)/1000,#N/A) -> #N/A | N43: =IF($B43>RECSYr,GETPIVOTDATA("HOUSEHOLDS",SqftTable!$A$7,"YEAR",B43),#N/A)/1000 -> #N/A | P43: =IF(ISERROR(G43/J43*1000),#N/A,G43/J43*1000) -> #N/A | Q43: =H43/K43*1000 -> #N/A | S43: =IFERROR(G43/M43*10^3,#N/A) -> #N/A | T43: =H43/N43*1000 -> #N/A | V43: =IFERROR(M43*1000/J43,#N/A) -> #N/A | W43: =N43*1000/K43 -> #N/A
B44: =B43+1 -> 1992 | C44: =IF($D44>LastSEDSyr,#N/A,SEDSDataPivots!I30) -> #VALUE! | D44: =D43+1 -> 1992 | E44: =IF($E$4=0,#N/A,IF(B44>=FirstNEMSYrPlot,GETPIVOTDATA("EQSTOCK",NEMSPriceFcast!$A$7,"YEAR",B44)*$D$9,#N/A)) -> #N/A | G44: =IF(G$16<1,#N/A,IF($D44>LastSEDSyr,#N/A,SEDSDataPivots!D30))/10^6 -> 0.014745 | H44: =IF(B44>=FirstNEMSYrPlot,GETPIVOTDATA("CONSUMPTION",NEMSConsFcast!$A$9,"YEAR",B44)/10^9,#N/A) -> #N/A | J44: =IFERROR(IF(GETPIVOTDATA("Sum of "&D44,'RECS Data'!$B$99)=0,#N/A,GETPIVOTDATA("Sum of "&D44,'RECS Data'!$B$99)),#N/A) -> #N/A | K44: =IF($B44>RECSYr,GETPIVOTDATA("HOUSEHOLDS",HousingStockTable!$A$12,"YEAR",B44)/10^6,#N/A) -> #N/A | M44: =IFERROR(IF(AND(B44<=RECSYr,GETPIVOTDATA("Sum of "&B44,'RECS Data'!$B$179)>0),GETPIVOTDATA("Sum of "&B44,'RECS Data'!$B$179),#N/A)/1000,#N/A) -> #N/A | N44: =IF($B44>RECSYr,GETPIVOTDATA("HOUSEHOLDS",SqftTable!$A$7,"YEAR",B44),#N/A)/1000 -> #N/A | P44: =IF(ISERROR(G44/J44*1000),#N/A,G44/J44*1000) -> #N/A | Q44: =H44/K44*1000 -> #N/A | S44: =IFERROR(G44/M44*10^3,#N/A) -> #N/A | T44: =H44/N44*1000 -> #N/A | V44: =IFERROR(M44*1000/J44,#N/A) -> #N/A | W44: =N44*1000/K44 -> #N/A
B45: =B44+1 -> 1993 | C45: =IF($D45>LastSEDSyr,#N/A,SEDSDataPivots!I31) -> #VALUE! | D45: =D44+1 -> 1993 | E45: =IF($E$4=0,#N/A,IF(B45>=FirstNEMSYrPlot,GETPIVOTDATA("EQSTOCK",NEMSPriceFcast!$A$7,"YEAR",B45)*$D$9,#N/A)) -> #N/A | G45: =IF(G$16<1,#N/A,IF($D45>LastSEDSyr,#N/A,SEDSDataPivots!D31))/10^6 -> 0.023475 | H45: =IF(B45>=FirstNEMSYrPlot,GETPIVOTDATA("CONSUMPTION",NEMSConsFcast!$A$9,"YEAR",B45)/10^9,#N/A) -> #N/A | J45: =IFERROR(IF(GETPIVOTDATA("Sum of "&D45,'RECS Data'!$B$99)=0,#N/A,GETPIVOTDATA("Sum of "&D45,'RECS Data'!$B$99)),#N/A) -> 96.631492 | K45: =IF($B45>RECSYr,GETPIVOTDATA("HOUSEHOLDS",HousingStockTable!$A$12,"YEAR",B45)/10^6,#N/A) -> #N/A | M45: =IFERROR(IF(AND(B45<=RECSYr,GETPIVOTDATA("Sum of "&B45,'RECS Data'!$B$179)>0),GETPIVOTDATA("Sum of "&B45,'RECS Data'!$B$179),#N/A)/1000,#N/A) -> 157.53553 | N45: =IF($B45>RECSYr,GETPIVOTDATA("HOUSEHOLDS",SqftTable!$A$7,"YEAR",B45),#N/A)/1000 -> #N/A | P45: =IF(ISERROR(G45/J45*1000),#N/A,G45/J45*1000) -> 0.24293323 | Q45: =H45/K45*1000 -> #N/A | S45: =IFERROR(G45/M45*10^3,#N/A) -> 0.14901401 | T45: =H45/N45*1000 -> #N/A | V45: =IFERROR(M45*1000/J45,#N/A) -> 1630.2711 | W45: =N45*1000/K45 -> #N/A
B46: =B45+1 -> 1994 | C46: =IF($D46>LastSEDSyr,#N/A,SEDSDataPivots!I32) -> #VALUE! | D46: =D45+1 -> 1994 | E46: =IF($E$4=0,#N/A,IF(B46>=FirstNEMSYrPlot,GETPIVOTDATA("EQSTOCK",NEMSPriceFcast!$A$7,"YEAR",B46)*$D$9,#N/A)) -> #N/A | G46: =IF(G$16<1,#N/A,IF($D46>LastSEDSyr,#N/A,SEDSDataPivots!D32))/10^6 -> 0.03185 | H46: =IF(B46>=FirstNEMSYrPlot,GETPIVOTDATA("CONSUMPTION",NEMSConsFcast!$A$9,"YEAR",B46)/10^9,#N/A) -> #N/A | J46: =IFERROR(IF(GETPIVOTDATA("Sum of "&D46,'RECS Data'!$B$99)=0,#N/A,GETPIVOTDATA("Sum of "&D46,'RECS Data'!$B$99)),#N/A) -> #N/A | K46: =IF($B46>RECSYr,GETPIVOTDATA("HOUSEHOLDS",HousingStockTable!$A$12,"YEAR",B46)/10^6,#N/A) -> #N/A | M46: =IFERROR(IF(AND(B46<=RECSYr,GETPIVOTDATA("Sum of "&B46,'RECS Data'!$B$179)>0),GETPIVOTDATA("Sum of "&B46,'RECS Data'!$B$179),#N/A)/1000,#N/A) -> #N/A | N46: =IF($B46>RECSYr,GETPIVOTDATA("HOUSEHOLDS",SqftTable!$A$7,"YEAR",B46),#N/A)/1000 -> #N/A | P46: =IF(ISERROR(G46/J46*1000),#N/A,G46/J46*1000) -> #N/A | Q46: =H46/K46*1000 -> #N/A | S46: =IFERROR(G46/M46*10^3,#N/A) -> #N/A | T46: =H46/N46*1000 -> #N/A | V46: =IFERROR(M46*1000/J46,#N/A) -> #N/A | W46: =N46*1000/K46 -> #N/A
B47: =B46+1 -> 1995 | C47: =IF($D47>LastSEDSyr,#N/A,SEDSDataPivots!I33) -> #VALUE! | D47: =D46+1 -> 1995 | E47: =IF($E$4=0,#N/A,IF(B47>=FirstNEMSYrPlot,GETPIVOTDATA("EQSTOCK",NEMSPriceFcast!$A$7,"YEAR",B47)*$D$9,#N/A)) -> #N/A | G47: =IF(G$16<1,#N/A,IF($D47>LastSEDSyr,#N/A,SEDSDataPivots!D33))/10^6 -> 0.013167 | H47: =IF(B47>=FirstNEMSYrPlot,GETPIVOTDATA("CONSUMPTION",NEMSConsFcast!$A$9,"YEAR",B47)/10^9,#N/A) -> #N/A | J47: =IFERROR(IF(GETPIVOTDATA("Sum of "&D47,'RECS Data'!$B$99)=0,#N/A,GETPIVOTDATA("Sum of "&D47,'RECS Data'!$B$99)),#N/A) -> #N/A | K47: =IF($B47>RECSYr,GETPIVOTDATA("HOUSEHOLDS",HousingStockTable!$A$12,"YEAR",B47)/10^6,#N/A) -> #N/A | M47: =IFERROR(IF(AND(B47<=RECSYr,GETPIVOTDATA("Sum of "&B47,'RECS Data'!$B$179)>0),GETPIVOTDATA("Sum of "&B47,'RECS Data'!$B$179),#N/A)/1000,#N/A) -> #N/A | N47: =IF($B47>RECSYr,GETPIVOTDATA("HOUSEHOLDS",SqftTable!$A$7,"YEAR",B47),#N/A)/1000 -> #N/A | P47: =IF(ISERROR(G47/J47*1000),#N/A,G47/J47*1000) -> #N/A | Q47: =H47/K47*1000 -> #N/A | S47: =IFERROR(G47/M47*10^3,#N/A) -> #N/A | T47: =H47/N47*1000 -> #N/A | V47: =IFERROR(M47*1000/J47,#N/A) -> #N/A | W47: =N47*1000/K47 -> #N/A
B48: =B47+1 -> 1996 | C48: =IF($D48>LastSEDSyr,#N/A,SEDSDataPivots!I34) -> #VALUE! | D48: =D47+1 -> 1996 | E48: =IF($E$4=0,#N/A,IF(B48>=FirstNEMSYrPlot,GETPIVOTDATA("EQSTOCK",NEMSPriceFcast!$A$7,"YEAR",B48)*$D$9,#N/A)) -> #N/A | G48: =IF(G$16<1,#N/A,IF($D48>LastSEDSyr,#N/A,SEDSDataPivots!D34))/10^6 -> 0.03361 | H48: =IF(B48>=FirstNEMSYrPlot,GETPIVOTDATA("CONSUMPTION",NEMSConsFcast!$A$9,"YEAR",B48)/10^9,#N/A) -> #N/A | J48: =IFERROR(IF(GETPIVOTDATA("Sum of "&D48,'RECS Data'!$B$99)=0,#N/A,GETPIVOTDATA("Sum of "&D48,'RECS Data'!$B$99)),#N/A) -> #N/A | K48: =IF($B48>RECSYr,GETPIVOTDATA("HOUSEHOLDS",HousingStockTable!$A$12,"YEAR",B48)/10^6,#N/A) -> #N/A | M48: =IFERROR(IF(AND(B48<=RECSYr,GETPIVOTDATA("Sum of "&B48,'RECS Data'!$B$179)>0),GETPIVOTDATA("Sum of "&B48,'RECS Data'!$B$179),#N/A)/1000,#N/A) -> #N/A | N48: =IF($B48>RECSYr,GETPIVOTDATA("HOUSEHOLDS",SqftTable!$A$7,"YEAR",B48),#N/A)/1000 -> #N/A | P48: =IF(ISERROR(G48/J48*1000),#N/A,G48/J48*1000) -> #N/A | Q48: =H48/K48*1000 -> #N/A | S48: =IFERROR(G48/M48*10^3,#N/A) -> #N/A | T48: =H48/N48*1000 -> #N/A | V48: =IFERROR(M48*1000/J48,#N/A) -> #N/A | W48: =N48*1000/K48 -> #N/A
B49: =B48+1 -> 1997 | C49: =IF($D49>LastSEDSyr,#N/A,SEDSDataPivots!I35) -> #VALUE! | D49: =D48+1 -> 1997 | E49: =IF($E$4=0,#N/A,IF(B49>=FirstNEMSYrPlot,GETPIVOTDATA("EQSTOCK",NEMSPriceFcast!$A$7,"YEAR",B49)*$D$9,#N/A)) -> #N/A | G49: =IF(G$16<1,#N/A,IF($D49>LastSEDSyr,#N/A,SEDSDataPivots!D35))/10^6 -> 0.033524 | H49: =IF(B49>=FirstNEMSYrPlot,GETPIVOTDATA("CONSUMPTION",NEMSConsFcast!$A$9,"YEAR",B49)/10^9,#N/A) -> #N/A | J49: =IFERROR(IF(GETPIVOTDATA("Sum of "&D49,'RECS Data'!$B$99)=0,#N/A,GETPIVOTDATA("Sum of "&D49,'RECS Data'!$B$99)),#N/A) -> 101.48117 | K49: =IF($B49>RECSYr,GETPIVOTDATA("HOUSEHOLDS",HousingStockTable!$A$12,"YEAR",B49)/10^6,#N/A) -> #N/A | M49: =IFERROR(IF(AND(B49<=RECSYr,GETPIVOTDATA("Sum of "&B49,'RECS Data'!$B$179)>0),GETPIVOTDATA("Sum of "&B49,'RECS Data'!$B$179),#N/A)/1000,#N/A) -> 168.80894 | N49: =IF($B49>RECSYr,GETPIVOTDATA("HOUSEHOLDS",SqftTable!$A$7,"YEAR",B49),#N/A)/1000 -> #N/A | P49: =IF(ISERROR(G49/J49*1000),#N/A,G49/J49*1000) -> 0.330347 | Q49: =H49/K49*1000 -> #N/A | S49: =IFERROR(G49/M49*10^3,#N/A) -> 0.19859138 | T49: =H49/N49*1000 -> #N/A | V49: =IFERROR(M49*1000/J49,#N/A) -> 1663.4508 | W49: =N49*1000/K49 -> #N/A
B50: =B49+1 -> 1998 | C50: =IF($D50>LastSEDSyr,#N/A,SEDSDataPivots!I36) -> #VALUE! | D50: =D49+1 -> 1998 | E50: =IF($E$4=0,#N/A,IF(B50>=FirstNEMSYrPlot,GETPIVOTDATA("EQSTOCK",NEMSPriceFcast!$A$7,"YEAR",B50)*$D$9,#N/A)) -> #N/A | G50: =IF(G$16<1,#N/A,IF($D50>LastSEDSyr,#N/A,SEDSDataPivots!D36))/10^6 -> 0.030814 | H50: =IF(B50>=FirstNEMSYrPlot,GETPIVOTDATA("CONSUMPTION",NEMSConsFcast!$A$9,"YEAR",B50)/10^9,#N/A) -> #N/A | J50: =IFERROR(IF(GETPIVOTDATA("Sum of "&D50,'RECS Data'!$B$99)=0,#N/A,GETPIVOTDATA("Sum of "&D50,'RECS Data'!$B$99)),#N/A) -> #N/A | K50: =IF($B50>RECSYr,GETPIVOTDATA("HOUSEHOLDS",HousingStockTable!$A$12,"YEAR",B50)/10^6,#N/A) -> #N/A | M50: =IFERROR(IF(AND(B50<=RECSYr,GETPIVOTDATA("Sum of "&B50,'RECS Data'!$B$179)>0),GETPIVOTDATA("Sum of "&B50,'RECS Data'!$B$179),#N/A)/1000,#N/A) -> #N/A | N50: =IF($B50>RECSYr,GETPIVOTDATA("HOUSEHOLDS",SqftTable!$A$7,"YEAR",B50),#N/A)/1000 -> #N/A | P50: =IF(ISERROR(G50/J50*1000),#N/A,G50/J50*1000) -> #N/A | Q50: =H50/K50*1000 -> #N/A | S50: =IFERROR(G50/M50*10^3,#N/A) -> #N/A | T50: =H50/N50*1000 -> #N/A | V50: =IFERROR(M50*1000/J50,#N/A) -> #N/A | W50: =N50*1000/K50 -> #N/A
B51: =B50+1 -> 1999 | C51: =IF($D51>LastSEDSyr,#N/A,SEDSDataPivots!I37) -> #VALUE! | D51: =D50+1 -> 1999 | E51: =IF($E$4=0,#N/A,IF(B51>=FirstNEMSYrPlot,GETPIVOTDATA("EQSTOCK",NEMSPriceFcast!$A$7,"YEAR",B51)*$D$9,#N/A)) -> #N/A | G51: =IF(G$16<1,#N/A,IF($D51>LastSEDSyr,#N/A,SEDSDataPivots!D37))/10^6 -> 0.024884 | H51: =IF(B51>=FirstNEMSYrPlot,GETPIVOTDATA("CONSUMPTION",NEMSConsFcast!$A$9,"YEAR",B51)/10^9,#N/A) -> #N/A | J51: =IFERROR(IF(GETPIVOTDATA("Sum of "&D51,'RECS Data'!$B$99)=0,#N/A,GETPIVOTDATA("Sum of "&D51,'RECS Data'!$B$99)),#N/A) -> #N/A | K51: =IF($B51>RECSYr,GETPIVOTDATA("HOUSEHOLDS",HousingStockTable!$A$12,"YEAR",B51)/10^6,#N/A) -> #N/A | M51: =IFERROR(IF(AND(B51<=RECSYr,GETPIVOTDATA("Sum of "&B51,'RECS Data'!$B$179)>0),GETPIVOTDATA("Sum of "&B51,'RECS Data'!$B$179),#N/A)/1000,#N/A) -> #N/A | N51: =IF($B51>RECSYr,GETPIVOTDATA("HOUSEHOLDS",SqftTable!$A$7,"YEAR",B51),#N/A)/1000 -> #N/A | P51: =IF(ISERROR(G51/J51*1000),#N/A,G51/J51*1000) -> #N/A | Q51: =H51/K51*1000 -> #N/A | S51: =IFERROR(G51/M51*10^3,#N/A) -> #N/A | T51: =H51/N51*1000 -> #N/A | V51: =IFERROR(M51*1000/J51,#N/A) -> #N/A | W51: =N51*1000/K51 -> #N/A
...

Sheet Units
B2: End-Use Equipment | C2: EQPCLASS (EquipStockTable) | D2: ENDUSE (EquipStockTable) | E2: Efficiency Metric | F2: RDM_DBOUT End Use
A3: Space Heating | F3: HT
B4: Air-Source Heat Pump | C4: ELEC_HP | D4: Heating | E4: Heating Seasonal Performance Factor (HSPF)
B5: Electric Furnace | C5: ELEC_RAD | D5: Heating | E5: Coefficient of Performance (COP)
B6: Distillate Fuel Oil/ Kerosene Boiler | C6: DIST_RAD | D6: Heating | E6: Annual Fuel Utilization Efficiency (AFUE)
B7: Distillate Fuel Oil/ Kerosene Furnace | C7: DIST_FA | D7: Heating | E7: AFUE
B8: Ground-Source Heat Pump | C8: GEO_HP | D8: Heating | E8: COP
B9: Propane Furnace | C9: LPG_FA | D9: Heating | E9: AFUE
B10: Natural Gas Boiler | C10: NG_RAD | D10: Heating | E10: AFUE
B11: Natural Gas Furnace | C11: NG_FA | D11: Heating | E11: AFUE
B12: Natural Gas Heat Pump | C12: NG_HP | D12: Heating | E12: COP
B13: Wood Stove | C13: WOOD_HT | D13: Heating | E13: COP
A14: Space Cooling | F14: CL
B15: Air-Source Heat Pump | C15: ELEC_HP | D15: Cooling | E15: Seasonal Energy Efficiency Ratio (SEER)
B16: Central Air Conditioner | C16: CENT_AIR | D16: Cooling | E16: SEER
B17: Ground-Source Heat Pump | C17: GEO_HP | D17: Cooling | E17: Energy Efficiency Ratio (EER)
B18: Natural Gas Heat Pump | C18: NG_HP | D18: Cooling | E18: COP
B19: Room Air Conditioner | C19: ROOM_AIR | D19: Cooling | E19: EER
A20: Water Heating | F20: HW
B21: Electricity Water Heater | C21: ELEC_WH | D21: HotWater | E21: Uniform Energy Factor (UEF)
B22: Distillate Fuel Oil/ Kerosene Water Heater | C22: DIST_WH | D22: HotWater | E22: UEF
B23: Propane Water Heater | C23: LPG_WH | D23: HotWater | E23: UEF
B24: Natural Gas Water Heater | C24: NG_WH | D24: HotWater | E24: UEF
B25: Solar Water Heater | C25: SOLAR_WH | D25: HotWater | E25: UEF
A26: Cooking | F26: CK
B27: Electric Cooking Range | C27: ELEC_STV | D27: Cooking | E27: kilowatthours per year (kWh/yr)
B28: Propane Cooking Range | C28: LPG_STV | D28: Cooking | E28: Thermal Efficiency (Btu Out / Btu In)
B29: Natural Gas Cooking Range | C29: NG_STV | D29: Cooking | E29: Thermal Efficiency (Btu Out / Btu In)
A30: Clothes Drying | F30: DR
B31: Electric Clothes Dryer | C31: ELEC_DRY | D31: Dryer | E31: Combined Energy Factor (CEF)
B32: Natural Gas Clothes Dryer | C32: NG_DRY | D32: Dryer | E32: CEF
A33: Clothes Washing | F33: CW
B34: Top-loading Clothes Washer | C34: CL_WASH | D34: ClothesWash | E34: kWh / cycle (motor), Modified Energy Factor (MEF), Water Factor (WF)
B35: Front-loading Clothes Washer | C35: CL_WASH | D35: ClothesWash | E35: kWh / cycle (motor), Modified Energy Factor (MEF), Water Factor (WF)
A36: Dishwashing | F36: DW
B37: Dishwasher | C37: DS_WASH | D37: DishWash | E37: cycles / kWh, kWh / year, gallons / cycle
A38: Refrigeration | F38: RF
B39: Refrigerator with top freezer (19 cubic foot capacity) | C39: REFR | D39: Refrigerator | E39: kWh / yr
B40: Refrigerator with side freezer (26 cubic foot capacity) | C40: REFR | D40: Refrigerator | E40: kWh / yr
B41: Refrigerator with bottom freezer (19 cubic foot capacity) | C41: REFR | D41: Refrigerator | E41: kWh / yr
...

Sheet NEMSPriceFcast
A1: 1987 $/mmBtu
A3: FUEL | B3: (All)
A4: CDIV | B4: (All)
A5: ENDUSE | B5: FP
A7: Sum of EQSTOCK
A8: YEAR | B8: Total
A9: 1990 | B9: 398.18
A10: 1991 | B10: 392.53
A11: 1992 | B11: 382.42
A12: 1993 | B12: 381.62
A13: 1994 | B13: 383.9
A14: 1995 | B14: 409.26
A15: 1996 | B15: 420.44
A16: 1997 | B16: 420.42
A17: 1998 | B17: 392.89
A18: 1999 | B18: 386.02
A19: 2000 | B19: 438.15
A20: 2001 | B20: 457.49
... A69: 2050 | B69: 562.97

Sheet NEMSConsFcast
A1: Delivered energy, mmBtu
A3: EQPCLASS | B3: (All)
A4: ENDUSE | B4: (Multiple Items)
A5: BLDG | B5: (All)
A6: FUEL | B6: (All)
A7: CDIV | B7: (All)
A9: Sum of CONSUMPTION
A10: YEAR | B10: Total
A11: 2020 | B11: 11222287378
A12: 2021 | B12: 11370043235
A13: 2022 | B13: 11906822378
A14: 2023 | B14: 11173912962
A15: 2024 | B15: 11123851170
A16: 2025 | B16: 11692794047
A17: 2026 | B17: 11495598106
A18: 2027 | B18: 11500735580
A19: 2028 | B19: 11527485697
A20: 2029 | B20: 11497263474
A21: 2030 | B21: 11431461455
A22: 2031 | B22: 11344948671
... A41: 2050 | B41: 11230169950

Sheet EquipStockTable
A1: Number of units (total stock)
A3: BLDG | B3: (All)
A4: CDIV | B4: (All)
A5: ENDUSE | B5: (All)
A6: FUEL | B6: (All)
A7: EQPCLASS | B7: (All)
A9: Sum of EQSTOCK
A10: YEAR | B10: Total
A11: 2020 | B11: 10280866567
A12: 2021 | B12: 10453704782
A13: 2022 | B13: 10651352454
A14: 2023 | B14: 10832271423
A15: 2024 | B15: 11006905883
A16: 2025 | B16: 11172515121
A17: 2026 | B17: 11336327071
A18: 2027 | B18: 11498094711
A19: 2028 | B19: 11654039352
A20: 2029 | B20: 11806276777
A21: 2030 | B21: 11954220390
A22: 2031 | B22: 12099210990
... A41: 2050 | B41: 14439403189

Sheet DetailedEquipTable
A1: Number of units (purchases)
A5: EQPTYPE | B5: (All)
A6: EQPCLASS | B6: (All)
A7: FUEL | B7: (All)
A8: ENDUSE | B8: (All)
A9: BLDG | B9: (All)
A10: CDIV | B10: (All)
B12: Data
A13: YEAR | B13: Sum of REPPURCHASE | C13: Sum of NEWPURCHASE | D13: Sum of TOTPURCHASE
A14: 2021 | B14: 848588696 | C14: 118918902 | D14: 967507598
A15: 2022 | B15: 670964105 | C15: 113644902 | D15: 784609007
A16: 2023 | B16: 658016637 | C16: 105749609 | D16: 763766246
A17: 2024 | B17: 585028294 | C17: 104081353 | D17: 689109647
A18: 2025 | B18: 545500900 | C18: 100594627 | D18: 646095527
A19: 2026 | B19: 530233403 | C19: 102127425 | D19: 632360828
A20: 2027 | B20: 501863035 | C20: 103200919 | D20: 605063954
A21: 2028 | B21: 502170839 | C21: 101913023 | D21: 604083862
A22: 2029 | B22: 516542600 | C22: 101878809 | D22: 618421409
A23: 2030 | B23: 520028945 | C23: 101142084 | D23: 621171029
A24: 2031 | B24: 540201913 | C24: 100582368 | D24: 640784281
A25: 2032 | B25: 549020071 | C25: 100329596 | D25: 649349667
... A43: 2050 | B43: 681351375 | C43: 74730064 | D43: 756081439

Sheet HousingStockTable
A1: Number of Households
A5: ENDUSE | B5: HT
A6: BLDG | B6: (All)
A7: CDIV | B7: (All)
A9: Sum of HOUSEHOLDS
A10: YEAR | B10: Total
A11: 2020 | B11: 123529024
A12: 2021 | B12: 125116611
A13: 2022 | B13: 126659565
A14: 2023 | B14: 128048589
A15: 2024 | B15: 129401591
A16: 2025 | B16: 130729203
A17: 2026 | B17: 132095186
A18: 2027 | B18: 133495360
A19: 2028 | B19: 134873478
A20: 2029 | B20: 136251925
A21: 2030 | B21: 137615488
A22: 2031 | B22: 138988196
... A41: 2050 | B41: 159101828

Sheet SqftTable
A1: Million Square Feet
A3: ENDUSE | B3: Squarefootage
A4: BLDG | B4: (All)
A5: CDIV | B5: (All)
A7: Sum of HOUSEHOLDS
A8: YEAR | B8: Total
A9: 2020 | B9: 199877
A10: 2021 | B10: 203298
A11: 2022 | B11: 206572
A12: 2023 | B12: 209614
A13: 2024 | B13: 212609
A14: 2025 | B14: 215504
A15: 2026 | B15: 218445
A16: 2027 | B16: 221422
A17: 2028 | B17: 224365
A18: 2029 | B18: 227308
A19: 2030 | B19: 230224
A20: 2031 | B20: 233120
... A39: 2050 | B39: 279776

Sheet HousingStartsTable
A1: Number of Starts
A6: BLDG | B6: (All)
A7: CDIV | B7: (All)
A9: Sum of EQSTOCK | B9: ENDUSE
A10: YEAR | B10: HousingStarts
A11: 2021 | B11: 1709000
A12: 2022 | B12: 1664084
A13: 2023 | B13: 1509999
A14: 2024 | B14: 1473418
A15: 2025 | B15: 1447719
A16: 2026 | B16: 1485832
A17: 2027 | B17: 1520279
A18: 2028 | B18: 1499065
A19: 2029 | B19: 1500317
A20: 2030 | B20: 1486238
A21: 2031 | B21: 1495565
A22: 2032 | B22: 1494399
... A40: 2050 | B40: 1018914

Sheet FuelSwitchingTable
A1: Number of units
A2: Model does not track specifically what fuels equipment are switched from and too (only THAT they are switching)
A6: BLDG | B6: (All)
A7: CDIV | B7: (All)
A9: Sum of EQSTOCK | B9: ENDUSE | C9: FUEL | D9: EQPCLASS
B10: SF | Q10: SF Total | R10: ST | AG10: ST Total
B11: Distillate | D11: Distillate Total | E11: EL | H11: EL Total | I11: Natural Gas | L11: Natural Gas Total | M11: Propane | N11: Propane Total | O11: Wood | P11: Wood Total | R11: Distillate | T11: Distillate Total | U11: EL | X11: EL Total | Y11: Natural Gas | AB11: Natural Gas Total | AC11: Propane | AD11: Propane Total | AE11: Wood | AF11: Wood Total
A12: YEAR | B12: DIST_FA | C12: DIST_RAD | E12: ELEC_HP | F12: ELEC_RAD | G12: GEO_HP | I12: NG_FA | J12: NG_HP | K12: NG_RAD | M12: LPG_FA | O12: WOOD_HT | R12: DIST_FA | S12: DIST_RAD | U12: ELEC_HP | V12: ELEC_RAD | W12: GEO_HP | Y12: NG_FA | Z12: NG_HP | AA12: NG_RAD | AC12: LPG_FA | AE12: WOOD_HT
A13: 2021 | B13: 19501 | C13: 1970 | D13: 21471 | E13: 11391 | F13: 3479 | G13: 0 | H13: 14870 | I13: 0 | J13: 0 | K13: 0 | L13: 0 | M13: 20970 | N13: 20970 | O13: 4838 | P13: 4838 | Q13: 62149 | R13: 271 | S13: 0 | T13: 271 | U13: 24208 | V13: 33849 | W13: 7 | X13: 58064 | Y13: 3774 | Z13: 0 | AA13: 9 | AB13: 3783 | AC13: 27 | AD13: 27 | AE13: 4 | AF13: 4 | AG13: 62149
A14: 2022 | B14: 32437 | C14: 7733 | D14: 40170 | E14: 10562 | F14: 4958 | G14: 0 | H14: 15520 | I14: 0 | J14: 0 | K14: 0 | L14: 0 | M14: 36521 | N14: 36521 | O14: 9081 | P14: 9081 | Q14: 101292 | R14: 1301 | S14: 0 | T14: 1301 | U14: 52631 | V14: 42218 | W14: 158 | X14: 95007 | Y14: 4962 | Z14: 0 | AA14: 12 | AB14: 4974 | AC14: 5 | AD14: 5 | AE14: 4 | AF14: 4 | AG14: 101291
A15: 2023 | B15: 32215 | C15: 3775 | D15: 35990 | E15: 11260 | F15: 4961 | G15: 0 | H15: 16221 | I15: 0 | J15: 0 | K15: 0 | L15: 0 | M15: 30831 | N15: 30831 | O15: 7733 | P15: 7733 | Q15: 90775 | R15: 182 | S15: 0 | T15: 182 | U15: 48366 | V15: 39196 | W15: 45 | X15: 87607 | Y15: 2932 | Z15: 0 | AA15: 10 | AB15: 2942 | AC15: 41 | AD15: 41 | AE15: 3 | AF15: 3 | AG15: 90775
A16: 2024 | B16: 31340 | C16: 2564 | D16: 33904 | E16: 11902 | F16: 4715 | G16: 0 | H16: 16617 | I16: 0 | J16: 0 | K16: 0 | L16: 0 | M16: 25066 | N16: 25066 | O16: 5606 | P16: 5606 | Q16: 81193 | R16: 120 | S16: 0 | T16: 120 | U16: 42153 | V16: 35537 | W16: 46 | X16: 77736 | Y16: 3249 | Z16: 0 | AA16: 14 | AB16: 3263 | AC16: 73 | AD16: 73 | AE16: 3 | AF16: 3 | AG16: 81195
A17: 2025 | B17: 31496 | C17: 3399 | D17: 34895 | E17: 10815 | F17: 5811 | G17: 0 | H17: 16626 | I17: 0 | J17: 0 | K17: 0 | L17: 0 | M17: 29030 | N17: 29030 | O17: 6801 | P17: 6801 | Q17: 87352 | R17: 423 | S17: 0 | T17: 423 | U17: 48052 | V17: 34847 | W17: 101 | X17: 83000 | Y17: 3840 | Z17: 0 | AA17: 9 | AB17: 3849 | AC17: 72 | AD17: 72 | AE17: 3 | AF17: 3 | AG17: 87347
A18: 2026 | B18: 29104 | C18: 1444 | D18: 30548 | E18: 12567 | F18: 5340 | G18: 0 | H18: 17907 | I18: 0 | J18: 0 | K18: 0 | L18: 0 | M18: 23426 | N18: 23426 | O18: 5115 | P18: 5115 | Q18: 76996 | R18: 216 | S18: 0 | T18: 216 | U18: 39911 | V18: 32992 | W18: 56 | X18: 72959 | Y18: 3674 | Z18: 0 | AA18: 8 | AB18: 3682 | AC18: 135 | AD18: 135 | AE18: 2 | AF18: 2 | AG18: 76994
A19: 2027 | B19: 29354 | C19: 2057 | D19: 31411 | E19: 14121 | F19: 5075 | G19: 0 | H19: 19196 | I19: 0 | J19: 0 | K19: 0 | L19: 0 | M19: 23116 | N19: 23116 | O19: 5048 | P19: 5048 | Q19: 78771 | R19: 210 | S19: 0 | T19: 210 | U19: 39598 | V19: 35160 | W19: 46 | X19: 74804 | Y19: 3601 | Z19: 0 | AA19: 8 | AB19: 3609 | AC19: 138 | AD19: 138 | AE19: 3 | AF19: 3 | AG19: 78764
A20: 2028 | B20: 28729 | C20: 2866 | D20: 31595 | E20: 15992 | F20: 4612 | G20: 0 | H20: 20604 | I20: 0 | J20: 0 | K20: 0 | L20: 0 | M20: 25922 | N20: 25922 | O20: 5438 | P20: 5438 | Q20: 83559 | R20: 211 | S20: 0 | T20: 211 | U20: 40532 | V20: 39681 | W20: 45 | X20: 80258 | Y20: 2982 | Z20: 0 | AA20: 10 | AB20: 2992 | AC20: 95 | AD20: 95 | AE20: 3 | AF20: 3 | AG20: 83559
A21: 2029 | B21: 27833 | C21: 3338 | D21: 31171 | E21: 16045 | F21: 4590 | G21: 0 | H21: 20635 | I21: 0 | J21: 0 | K21: 0 | L21: 0 | M21: 21755 | N21: 21755 | O21: 5576 | P21: 5576 | Q21: 79137 | R21: 223 | S21: 0 | T21: 223 | U21: 38118 | V21: 37921 | W21: 41 | X21: 76080 | Y21: 2660 | Z21: 0 | AA21: 10 | AB21: 2670 | AC21: 157 | AD21: 157 | AE21: 4 | AF21: 4 | AG21: 79134
A22: 2030 | B22: 27298 | C22: 3767 | D22: 31065 | E22: 16045 | F22: 4689 | G22: 0 | H22: 20734 | I22: 0 | J22: 0 | K22: 0 | L22: 0 | M22: 24114 | N22: 24114 | O22: 5885 | P22: 5885 | Q22: 81798 | R22: 251 | S22: 0 | T22: 251 | U22: 39205 | V22: 39314 | W22: 39 | X22: 78558 | Y22: 2845 | Z22: 0 | AA22: 12 | AB22: 2857 | AC22: 124 | AD22: 124 | AE22: 4 | AF22: 4 | AG22: 81794
A23: 2031 | B23: 26737 | C23: 3315 | D23: 30052 | E23: 15851 | F23: 4995 | G23: 0 | H23: 20846 | I23: 0 | J23: 0 | K23: 0 | L23: 0 | M23: 25600 | N23: 25600 | O23: 5882 | P23: 5882 | Q23: 82380 | R23: 285 | S23: 0 | T23: 285 | U23: 39170 | V23: 39370 | W23: 36 | X23: 78576 | Y23: 3401 | Z23: 0 | AA23: 12 | AB23: 3413 | AC23: 104 | AD23: 104 | AE23: 4 | AF23: 4 | AG23: 82382
A24: 2032 | B24: 25327 | C24: 3435 | D24: 28762 | E24: 15897 | F24: 4620 | G24: 0 | H24: 20517 | I24: 0 | J24: 0 | K24: 0 | L24: 0 | M24: 27059 | N24: 27059 | O24: 6321 | P24: 6321 | Q24: 82659 | R24: 291 | S24: 0 | T24: 291 | U24: 38860 | V24: 40464 | W24: 36 | X24: 79360 | Y24: 2918 | Z24: 0 | AA24: 10 | AB24: 2928 | AC24: 73 | AD24: 73 | AE24: 4 | AF24: 4 | AG24: 82656
... A42: 2050 | B42: 18115 | C42: 2087 | D42: 20202 | E42: 16770 | F42: 2646 | G42: 0 | H42: 19416 | I42: 0 | J42: 0 | K42: 0 | L42: 0 | M42: 21637 | N42: 21637 | O42: 4680 | P42: 4680 | Q42: 65935 | R42: 93 | S42: 0 | T42: 93 | U42: 25084 | V42: 39048 | W42: 13 | X42: 64145 | Y42: 1639 | Z42: 0 | AA42: 7 | AB42: 1646 | AC42: 46 | AD42: 46 | AE42: 4 | AF42: 4 | AG42: 65934

Sheet ShellTable
A1: Displays investment and subsidy, as well as annual new housing unit count, by shell type in this table -- note total expenditures on equipment or shell = consumer investment ("Sum of I_") + subsidy ("Sum of S_")
A2: i.e., total investment IECC2009 shells = S_IECC2009 + I_IECC2009; investments are in RTEKDOLLARYR dollars
A4: FUEL | B4: (All)
A5: BLDG | B5: (All)
A6: CDIV | B6: (All)
B8: Data
A9: YEAR | B9: Sum of S_BEST | C9: Sum of S_IECC+40% | D9: Sum of S_ESTAR | E9: Sum of S_IECC2009 | F9: Sum of S_NON_IECC09 | G9: Sum of I_BEST | H9: Sum of I_IECC+40% | I9: Sum of I_ESTAR | J9: Sum of I_IECC2009 | K9: Sum of I_NON_IECC09 | L9: Sum of BEST | M9: Sum of IECC+40% | N9: Sum of ESTAR | O9: Sum of IECC2009 | P9: Sum of NON_IECC09
A10: 2021 | B10: 100724957 | C10: 289362925 | D10: 0 | E10: 0 | F10: 0 | G10: 964417219 | H10: 2234537902 | I10: 2252871548 | J10: 4496338555 | K10: 0 | L10: 100051 | M10: 207570 | N10: 266832 | O10: 586264 | P10: 520474
A11: 2022 | B11: 253989944 | C11: 358224915 | D11: 0 | E11: 0 | F11: 0 | G11: 2408890247 | H11: 2744302503 | I11: 2533551420 | J11: 3764240671 | K11: 0 | L11: 238504 | M11: 249369 | N11: 300499 | O11: 506832 | P11: 368559
A12: 2023 | B12: 262931950 | C12: 608536442 | D12: 0 | E12: 0 | F12: 0 | G12: 1674164962 | H12: 3372084432 | I12: 2789593315 | J12: 2895361163 | K12: 0 | L12: 174086 | M12: 319293 | N12: 329889 | O12: 382356 | P12: 304062
A13: 2024 | B13: 253500950 | C13: 591853450 | D13: 0 | E13: 0 | F13: 0 | G13: 1599098584 | H13: 3248945210 | I13: 2914943622 | J13: 3097743396 | K13: 0 | L13: 152962 | M13: 293313 | N13: 328905 | O13: 385289 | P13: 312628
A14: 2025 | B14: 262298923 | C14: 601267914 | D14: 0 | E14: 0 | F14: 0 | G14: 1657329064 | H14: 3306690252 | I14: 2816195306 | J14: 2803470368 | K14: 0 | L14: 164049 | M14: 305893 | N14: 323762 | O14: 360175 | P14: 293407
A15: 2026 | B15: 152479431 | C15: 407612421 | D15: 0 | E15: 0 | F15: 0 | G15: 943997591 | H15: 2165269492 | I15: 1814026842 | J15: 4260662741 | K15: 0 | L15: 98743 | M15: 206311 | N15: 214608 | O15: 553480 | P15: 412247
A16: 2027 | B16: 0 | C16: 0 | D16: 0 | E16: 0 | F16: 0 | G16: 436481105 | H16: 894289738 | I16: 2251636717 | J16: 4904543769 | K16: 0 | L16: 60487 | M16: 105104 | N16: 265917 | O16: 641051 | P16: 447284
A17: 2028 | B17: 0 | C17: 0 | D17: 0 | E17: 0 | F17: 0 | G17: 429231307 | H17: 879047197 | I17: 2255637109 | J17: 4830313533 | K17: 0 | L17: 59177 | M17: 103084 | N17: 265411 | O17: 632810 | P17: 438155
A18: 2029 | B18: 0 | C18: 0 | D18: 0 | E18: 0 | F18: 0 | G18: 408345166 | H18: 934060732 | I18: 2485282872 | J18: 4617197637 | K18: 0 | L18: 57734 | M18: 109092 | N18: 289691 | O18: 609126 | P18: 434234
A19: 2030 | B19: 0 | C19: 0 | D19: 0 | E19: 0 | F19: 0 | G19: 416701726 | H19: 935121330 | I19: 2517587743 | J19: 4464625822 | K19: 0 | L19: 59427 | M19: 109571 | N19: 290897 | O19: 588777 | P19: 437148
A20: 2031 | B20: 0 | C20: 0 | D20: 0 | E20: 0 | F20: 0 | G20: 428777518 | H20: 944942364 | I20: 2534612464 | J20: 4373580998 | K20: 0 | L20: 62843 | M20: 113239 | N20: 295147 | O20: 585666 | P20: 438249
A21: 2032 | B21: 0 | C21: 0 | D21: 0 | E21: 0 | F21: 0 | G21: 432667731 | H21: 949502173 | I21: 2575557983 | J21: 4357033409 | K21: 0 | L21: 63056 | M21: 113560 | N21: 299181 | O21: 583921 | P21: 434255
... A39: 2050 | B39: 0 | C39: 0 | D39: 0 | E39: 0 | F39: 0 | G39: 311602761 | H39: 715456185 | I39: 2269423472 | J39: 2960854729 | K39: 0 | L39: 40786 | M39: 79912 | N39: 253998 | O39: 388499 | P39: 255267

Sheet ShellIndexTable
A1: Shell heating and cooling indices
A2: Index relative to RECS base year
A8: Sum of EQSTOCK | B8: ENDUSE
A9: YEAR | B9: CoolingIndexExisting | C9: CoolingIndexNew | D9: HeatingIndexExisting | E9: HeatingIndexNew
A10: 2020 | B10: 1 | C10: 1 | D10: 1 | E10: 1
A11: 2021 | B11: 0.99599755 | C11: 1.0091649 | D11: 0.98736274 | E11: 0.87648463
A12: 2022 | B12: 0.99208128 | C12: 0.99479604 | D12: 0.97692734 | E12: 0.81995225
A13: 2023 | B13: 0.98891568 | C13: 0.98634046 | D13: 0.96806389 | E13: 0.80307013
A14: 2024 | B14: 0.98679149 | C14: 0.9727568 | D14: 0.96188825 | E14: 0.78982347
A15: 2025 | B15: 0.98486483 | C15: 0.97893178 | D15: 0.95610034 | E15: 0.78972036
A16: 2026 | B16: 0.98308736 | C16: 1.0064977 | D16: 0.95072538 | E16: 0.86565924
A17: 2027 | B17: 0.98110241 | C17: 1.0235671 | D17: 0.94496751 | E17: 0.90141785
A18: 2028 | B18: 0.97895038 | C18: 1.0234783 | D18: 0.93891299 | E18: 0.90078545
A19: 2029 | B19: 0.97653568 | C19: 1.0224497 | D19: 0.93220139 | E19: 0.8984645
A20: 2030 | B20: 0.97393119 | C20: 1.0225478 | D20: 0.92494178 | E20: 0.90203619
A21: 2031 | B21: 0.97123021 | C21: 1.0262849 | D21: 0.91736883 | E21: 0.90737224
... A40: 2050 | B40: 0.92522109 | C40: 1.0139691 | D40: 0.78784168 | E40: 0.875063

Sheet EfficiencyTable
A1: See Units tab for efficiency metric by end use
A6: CDIV | B6: (All)
A7: ENDUSE | B7: Heating
A8: BLDG | B8: (All)
B10: Data | C10: EQPCLASS
B11: Average of EXEFF | L11: Average of NEWEFF
A12: YEAR | B12: DIST_FA | C12: DIST_RAD | D12: ELEC_HP | E12: ELEC_RAD | F12: GEO_HP | G12: LPG_FA | H12: NG_FA | I12: NG_HP | J12: NG_RAD | K12: WOOD_HT | L12: DIST_FA | M12: DIST_RAD | N12: ELEC_HP | O12: ELEC_RAD | P12: GEO_HP | Q12: LPG_FA | R12: NG_FA | S12: NG_HP | T12: NG_RAD | U12: WOOD_HT
A13: 2021 | B13: 0.8310037 | C13: 0.84204444 | D13: 8.0034889 | E13: 0.98110741 | F13: 3.1136852 | G13: 0.80365556 | H13: 0.80393704 | I13: 1.3 | J13: 0.8234037 | K13: 0.63354074 | L13: 0.59266667 | M13: 0.63865556 | N13: 8.9736074 | O13: 0.99715185 | P13: 2.5013852 | Q13: 0.8126037 | R13: 0.87658889 | S13: 0.96296296 | T13: 0.84302222 | U13: 0.58282222
A14: 2022 | B14: 0.83172593 | C14: 0.84278148 | D14: 8.1258407 | E14: 0.98223704 | F14: 3.1284 | G14: 0.80794074 | H14: 0.80845556 | I14: 1.3 | J14: 0.8272963 | K14: 0.63733704 | L14: 0.59014444 | M14: 0.63836296 | N14: 9.0035296 | O14: 0.99688519 | P14: 2.5100444 | Q14: 0.81754815 | R14: 0.88221852 | S14: 0.96296296 | T14: 0.84745556 | U14: 0.5828
A15: 2023 | B15: 0.83228519 | C15: 0.84331852 | D15: 8.2612148 | E15: 0.9833963 | F15: 3.1444926 | G15: 0.81227037 | H15: 0.81305926 | I15: 1.3 | J15: 0.83107407 | K15: 0.64108148 | L15: 0.59385185 | M15: 0.6393 | N15: 9.4626556 | O15: 0.99801481 | P15: 2.5187556 | Q15: 0.8199 | R15: 0.88624074 | S15: 0.96296296 | T15: 0.84747037 | U15: 0.58338889
A16: 2024 | B16: 0.83286296 | C16: 0.84386296 | D16: 8.3852074 | E16: 0.98448889 | F16: 3.1600815 | G16: 0.8166 | H16: 0.81767778 | I16: 1.3 | J16: 0.83484815 | K16: 0.6449 | L16: 0.59451111 | M16: 0.63951852 | N16: 9.4536185 | O16: 0.99751111 | P16: 2.5184593 | Q16: 0.82015185 | R16: 0.88636296 | S16: 0.96296296 | T16: 0.84747778 | U16: 0.58365185
A17: 2025 | B17: 0.8388 | C17: 0.85148889 | D17: 8.5539222 | E17: 0.98554444 | F17: 3.2874407 | G17: 0.82864815 | H17: 0.8223963 | I17: 1.3 | J17: 0.84341852 | K17: 0.67143704 | L17: 0.84515556 | M17: 0.86412963 | N17: 9.8613852 | O17: 0.99736667 | P17: 3.5470074 | Q17: 0.88758148 | R17: 0.88595556 | S17: 1.3 | T17: 0.91315185 | U17: 0.74514444
A18: 2026 | B18: 0.83836296 | C18: 0.85168148 | D18: 8.6721926 | E18: 0.98656667 | F18: 3.2762407 | G18: 0.8313963 | H18: 0.82668889 | I18: 1.3 | J18: 0.84644444 | K18: 0.67322593 | L18: 0.84304815 | M18: 0.86345556 | N18: 9.8012407 | O18: 0.99741481 | P18: 3.441737 | Q18: 0.87757407 | R18: 0.87803333 | S18: 1.3 | T18: 0.90947407 | U18: 0.73541481
A19: 2027 | B19: 0.83815926 | C19: 0.85198519 | D19: 8.7928185 | E19: 0.98762593 | F19: 3.2778519 | G19: 0.83468519 | H19: 0.83084815 | I19: 1.3 | J19: 0.84923333 | K19: 0.67597407 | L19: 0.84188519 | M19: 0.86306667 | N19: 9.7834556 | O19: 0.99804815 | P19: 3.4288296 | Q19: 0.87426667 | R19: 0.8753963 | S19: 1.3 | T19: 0.90747037 | U19: 0.73505185
A20: 2028 | B20: 0.83831111 | C20: 0.85243333 | D20: 8.9179889 | E20: 0.98866296 | F20: 3.2858074 | G20: 0.83829259 | H20: 0.83501481 | I20: 1.3 | J20: 0.85228148 | K20: 0.67898519 | L20: 0.84184815 | M20: 0.86306667 | N20: 9.7864667 | O20: 0.99807778 | P20: 3.4317519 | Q20: 0.87426296 | R20: 0.87568889 | S20: 1.3 | T20: 0.90762222 | U20: 0.7350963
A21: 2029 | B21: 0.83858148 | C21: 0.85293704 | D21: 9.034363 | E21: 0.98966296 | F21: 3.2962519 | G21: 0.8479037 | H21: 0.84354815 | I21: 1.3 | J21: 0.85544074 | K21: 0.6821037 | L21: 0.84182963 | M21: 0.86305926 | N21: 9.7842333 | O21: 0.99807407 | P21: 3.4349963 | Q21: 0.9463 | R21: 0.94436667 | S21: 1.3 | T21: 0.90781111 | U21: 0.73513333
A22: 2030 | B22: 0.83891111 | C22: 0.85347778 | D22: 9.1423667 | E22: 0.99063704 | F22: 3.3080593 | G22: 0.85742593 | H22: 0.85276667 | I22: 1.3 | J22: 0.85867037 | K22: 0.68524815 | L22: 0.84185556 | M22: 0.86306667 | N22: 9.7913481 | O22: 0.99806667 | P22: 3.439863 | Q22: 0.95994444 | R22: 0.9598 | S22: 1.3 | T22: 0.90816296 | U22: 0.73525556
A23: 2031 | B23: 0.83927037 | C23: 0.85404074 | D23: 9.241937 | E23: 0.99161481 | F23: 3.3207444 | G23: 0.86677037 | H23: 0.86209259 | I23: 1.3 | J23: 0.86188889 | K23: 0.68836667 | L23: 0.84195926 | M23: 0.86310741 | N23: 9.7937148 | O23: 0.99807037 | P23: 3.4437556 | Q23: 0.95994815 | R23: 0.95981111 | S23: 1.3 | T23: 0.90828889 | U23: 0.73525185
A24: 2032 | B24: 0.83963333 | C24: 0.85465185 | D24: 9.3328815 | E24: 0.99252222 | F24: 3.3333333 | G24: 0.87544444 | H24: 0.8709037 | I24: 1.3 | J24: 0.86508889 | K24: 0.6915 | L24: 0.84204074 | M24: 0.86312963 | N24: 9.7908 | O24: 0.9981 | P24: 3.4470889 | Q24: 0.95994815 | R24: 0.95984444 | S24: 1.3 | T24: 0.90845926 | U24: 0.73531111
... A42: 2050 | B42: 0.84314444 | C42: 0.86334444 | D42: 9.7852444 | E42: 0.99886296 | F42: 3.474763 | G42: 0.95089259 | H42: 0.95101111 | I42: 1.3 | J42: 0.90982222 | K42: 0.73825185 | L42: 0.8449037 | M42: 0.86362963 | N42: 9.806937 | O42: 1 | P42: 3.4900296 | Q42: 0.96047778 | R42: 0.96052222 | S42: 1.3 | T42: 0.91014815 | U42: 0.74064074

Sheet EStarEquipTable
A1: Number of units
A4: EQPTYPE | B4: (All)
A5: EQPCLASS | B5: (All)
A6: ENDUSE | B6: (All)
A7: FUEL | B7: (All)
A8: BLDG | B8: (All)
A9: CDIV | B9: (All)
A11: Sum of TotalPurchase
A12: YEAR | B12: Total
A13: 2021 | B13: 929979439
A14: 2022 | B14: 748158724
A15: 2023 | B15: 724788049
A16: 2024 | B16: 650295934
A17: 2025 | B17: 605719973
A18: 2026 | B18: 588194362
A19: 2027 | B19: 554173095
A20: 2028 | B20: 546681418
A21: 2029 | B21: 555736396
A22: 2030 | B22: 553488675
A23: 2031 | B23: 571345098
A24: 2032 | B24: 578138027
... A42: 2050 | B42: 685362810

Sheet InvestmentTable
A1: Displays Investment and Subsidy on the Shell and Investment Tables -- note total expenditures on equipment or shell = consumer investment ("Investment") + subsidy; subsidy includes both federal and non-federal subsidies
A2: i.e., total investment = totinvest + totsubsidy ; investments are in RTEKDOLLARYR dollars
A4: EQPTYPE | B4: (All)
A5: EQPCLASS | B5: (All)
A6: ENDUSE | B6: (All)
A7: FUEL | B7: (All)
A8: BLDG | B8: (All)
A9: CDIV | B9: (All)
B11: Data
A12: YEAR | B12: Sum of TOTSUBSIDY | C12: Sum of TOTPURCHASE | D12: Sum of TOTINVEST
A13: 2021 | B13: 4472798088 | C13: 967507598 | D13: 71938491422
A14: 2022 | B14: 7158870701 | C14: 784609007 | D14: 74538591190
A15: 2023 | B15: 7562323469 | C15: 763766246 | D15: 77121192434
A16: 2024 | B16: 7745695479 | C16: 689109647 | D16: 78979163967
A17: 2025 | B17: 7995993722 | C17: 646095527 | D17: 81029874976
A18: 2026 | B18: 1842680019 | C18: 632360828 | D18: 79738776927
A19: 2027 | B19: 1913579632 | C19: 605063954 | D19: 84897380618
A20: 2028 | B20: 1898814186 | C20: 604083862 | D20: 89055794763
A21: 2029 | B21: 1472502548 | C21: 618421409 | D21: 91456663659
A22: 2030 | B22: 1394884629 | C22: 621171029 | D22: 95291973926
A23: 2031 | B23: 1433275466 | C23: 640784281 | D23: 97553837391
A24: 2032 | B24: 1439643648 | C24: 649349667 | D24: 99197926933
... A42: 2050 | B42: 1442542694 | C42: 756081439 | D42: 99157867511

Sheet SEDSDataPivots
C2: SEDS consumption (billion Btu) | F2: SEDS expenditure (million dollars) | I2: <-- Refresh/expand source for pivot tables after using EIA & FRED Data add-on to refresh data in SEDS_CONS_API and SEDS_EXP_API tabs
C4: Division | D4: (All) | F4: Division | G4: (All) | I4: Note that SEDS Solar consumption includes distributed PV and solar thermal energy consumed by the residential, commercial, and industrial sectors, other than power generated at commercial and industrial facilities with capacity of 1 MW or greater
C5: Fuel | D5: Electricity | F5: Fuel | G5: Electricity
B7: Year | C7: Row Labels | F7: Row Labels | I7: =Deflators!B5&"$ per 1,000 MMBtu" -> 2022$ per 1,000 MMBtu | K7: Deflator
B8: =VALUE(MID(C8,8,4)) -> 1970 | C8: Sum of 1970-01-012 | F8: Sum of 1970-01-012 | I8: =IF(D8>0,G8/D8*1000/K8,#N/A) -> #N/A | K8: =HLOOKUP(B8,Deflators!$D$2:$BG$5,4,0) -> 0.17105568
B9: =VALUE(MID(C9,8,4)) -> #VALUE! | C9: 6997 | D9: 1798 | F9: 337.9 | G9: 15.5 | I9: =IF(D9>0,G9/D9*1000/K9,#N/A) -> #VALUE! | K9: =HLOOKUP(B9,Deflators!$D$2:$BG$5,4,0) -> #VALUE!
B10: =VALUE(MID(C10,8,4)) -> #VALUE! | C10: 7426 | D10: 4150 | F10: 390 | G10: 19.9 | I10: =IF(D10>0,G10/D10*1000/K10,#N/A) -> #VALUE! | K10: =HLOOKUP(B10,Deflators!$D$2:$BG$5,4,0) -> #VALUE!
B11: =VALUE(MID(C11,8,4)) -> #VALUE! | C11: 8092 | D11: 2832 | F11: 453.1 | G11: 27.7 | I11: =IF(D11>0,G11/D11*1000/K11,#N/A) -> #VALUE! | K11: =HLOOKUP(B11,Deflators!$D$2:$BG$5,4,0) -> #VALUE!
B12: =VALUE(MID(C12,8,4)) -> #VALUE! | C12: 9189 | D12: 4384 | F12: 557.9 | G12: 37.2 | I12: =IF(D12>0,G12/D12*1000/K12,#N/A) -> #VALUE! | K12: =HLOOKUP(B12,Deflators!$D$2:$BG$5,4,0) -> #VALUE!
B13: =VALUE(MID(C13,8,4)) -> #VALUE! | C13: 10058 | D13: 2059 | F13: 646.5 | G13: 42 | I13: =IF(D13>0,G13/D13*1000/K13,#N/A) -> #VALUE! | K13: =HLOOKUP(B13,Deflators!$D$2:$BG$5,4,0) -> #VALUE!
B14: =VALUE(MID(C14,8,4)) -> #VALUE! | C14: 10219 | D14: 4742 | F14: 721.7 | G14: 34.4 | I14: =IF(D14>0,G14/D14*1000/K14,#N/A) -> #VALUE! | K14: =HLOOKUP(B14,Deflators!$D$2:$BG$5,4,0) -> #VALUE!
B15: =VALUE(MID(C15,8,4)) -> #VALUE! | C15: 15883 | D15: 5037 | F15: 775.8 | G15: 30 | I15: =IF(D15>0,G15/D15*1000/K15,#N/A) -> #VALUE! | K15: =HLOOKUP(B15,Deflators!$D$2:$BG$5,4,0) -> #VALUE!
B16: =VALUE(MID(C16,8,4)) -> #VALUE! | C16: 16783 | D16: 5878 | F16: 809.2 | G16: 40 | I16: =IF(D16>0,G16/D16*1000/K16,#N/A) -> #VALUE! | K16: =HLOOKUP(B16,Deflators!$D$2:$BG$5,4,0) -> #VALUE!
B17: =VALUE(MID(C17,8,4)) -> #VALUE! | C17: 16827 | D17: 3988 | F17: 1015.8 | G17: 41 | I17: =IF(D17>0,G17/D17*1000/K17,#N/A) -> #VALUE! | K17: =HLOOKUP(B17,Deflators!$D$2:$BG$5,4,0) -> #VALUE!
B18: =VALUE(MID(C18,8,4)) -> #VALUE! | C18: 17289 | D18: 4775 | F18: 1082.5 | G18: 38.6 | I18: =IF(D18>0,G18/D18*1000/K18,#N/A) -> #VALUE! | K18: =HLOOKUP(B18,Deflators!$D$2:$BG$5,4,0) -> #VALUE!
B19: =VALUE(MID(C19,8,4)) -> #VALUE! | C19: 17899 | D19: 5411 | F19: 1141.7 | G19: 36 | I19: =IF(D19>0,G19/D19*1000/K19,#N/A) -> #VALUE! | K19: =HLOOKUP(B19,Deflators!$D$2:$BG$5,4,0) -> #VALUE!
B20: =VALUE(MID(C20,8,4)) -> #VALUE! | C20: 19638 | D20: 5234 | F20: 1195.2 | G20: 87 | I20: =IF(D20>0,G20/D20*1000/K20,#N/A) -> #VALUE! | K20: =HLOOKUP(B20,Deflators!$D$2:$BG$5,4,0) -> #VALUE!
... B58: =VALUE(MID(C58,8,4)) -> #VALUE! | C58: 463367 | D58: 83969 | F58: 10932.2 | G58: 413.2 | I58: =IF(D58>0,G58/D58*1000/K58,#N/A) -> #VALUE! | K58: =HLOOKUP(B58,Deflators!$D$2:$BG$5,4,0) -> #VALUE!
B59: =VALUE(MID(C59,8,4)) -> #VALUE! | C59: 575300 | D59: 111201 | F59: Sum of 1971-01-01 | I59: =IF(D59>0,G59/D59*1000/K59,#N/A) -> #VALUE! | K59: =HLOOKUP(B59,Deflators!$D$2:$BG$5,4,0) -> #VALUE!
B60: =VALUE(MID(C60,8,4)) -> 1971 | C60: Sum of 1971-01-01 | F60: 337.9 | G60: 16.8 | I60: =IF(D60>0,G60/D60*1000/K60,#N/A) -> #N/A | K60: =HLOOKUP(B60,Deflators!$D$2:$BG$5,4,0) -> 0.17973786
B61: =VALUE(MID(C61,8,4)) -> #VALUE! | C61: 6997 | D61: 2155 | F61: 390 | G61: 22.6 | I61: =IF(D61>0,G61/D61*1000/K61,#N/A) -> #VALUE! | K61: =HLOOKUP(B61,Deflators!$D$2:$BG$5,4,0) -> #VALUE!
C62: 7426 | D62: 4640 | F62: 453.1 | G62: 31.8
C63: 8092 | D63: 2925 | F63: 557.9 | G63: 39.3
C64: 9189 | D64: 4745 | F64: 646.5 | G64: 44.1
C65: 10058 | D65: 2231 | F65: 721.7 | G65: 36.6
C66: 10219 | D66: 5143 | F66: 775.8 | G66: 34.5
C67: 15883 | D67: 5686 | F67: 809.2 | G67: 44.2
C68: 16783 | D68: 6441 | F68: 1015.8 | G68: 45.4
C69: 16827 | D69: 4260 | F69: 1082.5 | G69: 43.7
C70: 17289 | D70: 5021 | F70: 1141.7 | G70: 41
C71: 17899 | D71: 5682 | F71: 1195.2 | G71: 95.9
C72: 19638 | D72: 5570 | F72: 1268.5 | G72: 44.2
C73: 25031 | D73: 5559 | F73: 1310.5 | G73: 46
... C109: 282585 | D109: 133301 | F109: 10932.2 | G109: 465.6
C110: 463367 | D110: 92893 | F110: Sum of 1972-01-01
C111: 575300 | D111: 122764 | F111: 337.9 | G111: 18.3
C112: Sum of 1972-01-01 | F112: 390 | G112: 23.7
C113: 6997 | D113: 2143 | F113: 453.1 | G113: 38.6
C114: 7426 | D114: 5105 | F114: 557.9 | G114: 43.7
C115: 8092 | D115: 2942 | F115: 646.5 | G115: 48.3
...

Sheet SEDS_CONS_API
A1: 1date | B1: A | C1: 25569 | D1: 44197 | E1: Source | F1: date | G1: 45292 | H1: 44927 | I1: 44562 | J1: 44197 | K1: 43831 | L1: 43466 | M1: 43101 | N1: 42736 | O1: 42370 | P1: 42005 | Q1: 41640 | R1: 41275 | S1: 40909 | T1: 40544 | U1: 40179 | V1: 39814 | W1: 39448 | X1: 39083 | Y1: 38718 | Z1: 38353 | AA1: 37987 | AB1: 37622 | AC1: 37257 | AD1: 36892 | AE1: 36526 | AF1: 36161 | AG1: 35796 | AH1: 35431 | AI1: 35065 | AJ1: 34700 | AK1: 34335 | AL1: 33970 | AM1: 33604 | AN1: 33239 | AO1: 32874 | AP1: 32509 | AQ1: 32143 | AR1: 31778 | AS1: 31413 | AT1: 31048 | AU1: 30682 | AV1: 30317 | AW1: 29952 | AX1: 29587 | AY1: 29221 | AZ1: 28856 | BA1: 28491 | BB1: 28126 | BC1: 27760 | BD1: 27395 | BE1: 27030 | BF1: 26665 | BG1: 26299 | BH1: 25934 | BI1: 25569 | BJ1: Division | BK1: Fuel
A2: SEDS.ESRCB.AL.A | C2: Billion Btu | E2: EIA, U.S. Energy Information Administration | F2: value | G2: 112252 | H2: 107170 | I2: 112335 | J2: 107769 | K2: 106902 | L2: 110602 | M2: 112870 | N2: 102978 | O2: 109374 | P2: 108872 | Q2: 112356 | R2: 107064 | S2: 104517 | T2: 112606 | U2: 121226 | V2: 107442 | W2: 109814 | X2: 111857 | Y2: 110129 | Z2: 106847 | AA2: 102732 | AB2: 100369 | AC2: 102434 | AD2: 94861 | AE2: 98116 | AF2: 92287 | AG2: 93240 | AH2: 84935 | AI2: 87463 | AJ2: 82959 | AK2: 79017 | AL2: 77206 | AM2: 72118 | AN2: 72653 | AO2: 70692 | AP2: 67702 | AQ2: 67015 | AR2: 65833 | AS2: 62299 | AT2: 58626 | AU2: 58046 | AV2: 53958 | AW2: 53847 | AX2: 54291 | AY2: 56192 | AZ2: 51279 | BA2: 53701 | BB2: 52022 | BC2: 48066 | BD2: 45752 | BE2: 50113 | BF2: 50171 | BG2: 45542 | BH2: 41754 | BI2: 39331 | BJ2: =VLOOKUP(MID(A2,12,2),'State Codes'!$B$10:$D$60,3,0) -> 6 East South Central | BK2: =VLOOKUP(MID(A2,6,5),'Chart Controls'!$P$3:$Q$8,2,0) -> Electricity
A3: SEDS.ESRCB.AK.A | C3: Billion Btu | E3: EIA, U.S. Energy Information Administration | F3: value | G3: 7065 | H3: 6997 | I3: 6996 | J3: 7110 | K3: 7128 | L3: 6579 | M3: 6738 | N3: 7030 | O3: 6846 | P3: 6975 | Q3: 6973 | R3: 7179 | S3: 7371 | T3: 7283 | U3: 7142 | V3: 7225 | W3: 7267 | X3: 7215 | Y3: 7234 | Z3: 7034 | AA3: 7035 | AB3: 6780 | AC3: 6593 | AD3: 6454 | AE3: 6329 | AF3: 6366 | AG3: 6032 | AH3: 5889 | AI3: 6026 | AJ3: 5844 | AK3: 5760 | AL3: 5558 | AM3: 5596 | AN3: 5469 | AO3: 5668 | AP3: 5607 | AQ3: 5426 | AR3: 5283 | AS3: 5544 | AT3: 5711 | AU3: 5450 | AV3: 4959 | AW3: 4805 | AX3: 4190 | AY3: 3726 | AZ3: 3641 | BA3: 3787 | BB3: 3655 | BC3: 3355 | BD3: 3063 | BE3: 2574 | BF3: 2342 | BG3: 2143 | BH3: 2155 | BI3: 1798 | BJ3: =VLOOKUP(MID(A3,12,2),'State Codes'!$B$10:$D$60,3,0) -> 9 Pacific | BK3: =VLOOKUP(MID(A3,6,5),'Chart Controls'!$P$3:$Q$8,2,0) -> Electricity
A4: SEDS.ESRCB.AZ.A | C4: Billion Btu | E4: EIA, U.S. Energy Information Administration | F4: value | G4: 137964 | H4: 133042 | I4: 130910 | J4: 126689 | K4: 132070 | L4: 118465 | M4: 118261 | N4: 116865 | O4: 114953 | P4: 113167 | Q4: 110365 | R4: 112949 | S4: 112333 | T4: 112866 | U4: 110713 | V4: 112073 | W4: 113402 | X4: 117498 | Y4: 110438 | Z4: 104215 | AA4: 98677 | AB4: 94654 | AC4: 90120 | AD4: 89395 | AE4: 84768 | AF4: 76829 | AG4: 73736 | AH4: 70569 | AI4: 67375 | AJ4: 61537 | AK4: 62141 | AL4: 56998 | AM4: 55378 | AN4: 53369 | AO4: 52469 | AP4: 52024 | AQ4: 50262 | AR4: 47156 | AS4: 42785 | AT4: 41794 | AU4: 37908 | AV4: 35576 | AW4: 32426 | AX4: 32516 | AY4: 32881 | AZ4: 31745 | BA4: 28634 | BB4: 26800 | BC4: 24903 | BD4: 24353 | BE4: 24209 | BF4: 22918 | BG4: 19851 | BH4: 16825 | BI4: 14765 | BJ4: =VLOOKUP(MID(A4,12,2),'State Codes'!$B$10:$D$60,3,0) -> 8 Mountain | BK4: =VLOOKUP(MID(A4,6,5),'Chart Controls'!$P$3:$Q$8,2,0) -> Electricity
A5: SEDS.ESRCB.AR.A | C5: Billion Btu | E5: EIA, U.S. Energy Information Administration | F5: value | G5: 63397 | H5: 62692 | I5: 65683 | J5: 64548 | K5: 61348 | L5: 63915 | M5: 65712 | N5: 58095 | O5: 60680 | P5: 62349 | Q5: 62921 | R5: 62164 | S5: 61107 | T5: 64102 | U5: 65616 | V5: 57955 | W5: 59343 | X5: 59418 | Y5: 58226 | Z5: 58460 | AA5: 53293 | AB5: 53221 | AC5: 52979 | AD5: 51535 | AE5: 50739 | AF5: 47923 | AG5: 48926 | AH5: 44321 | AI5: 44131 | AJ5: 42367 | AK5: 39723 | AL5: 40131 | AM5: 35622 | AN5: 37534 | AO5: 36023 | AP5: 33974 | AQ5: 33935 | AR5: 33122 | AS5: 31574 | AT5: 30489 | AU5: 29901 | AV5: 30017 | AW5: 29401 | AX5: 28751 | AY5: 34895 | AZ5: 30237 | BA5: 31807 | BB5: 30081 | BC5: 26429 | BD5: 26447 | BE5: 20753 | BF5: 20955 | BG5: 18709 | BH5: 16164 | BI5: 14745 | BJ5: =VLOOKUP(MID(A5,12,2),'State Codes'!$B$10:$D$60,3,0) -> 7 West South Central | BK5: =VLOOKUP(MID(A5,6,5),'Chart Controls'!$P$3:$Q$8,2,0) -> Electricity
A6: SEDS.ESRCB.CA.A | C6: Billion Btu | E6: EIA, U.S. Energy Information Administration | F6: value | G6: 292922 | H6: 282585 | I6: 305518 | J6: 308049 | K6: 323917 | L6: 298632 | M6: 304009 | N6: 307501 | O6: 301317 | P6: 304986 | Q6: 304899 | R6: 304493 | S6: 307455 | T6: 301615 | U6: 297721 | V6: 306393 | W6: 311280 | X6: 304209 | Y6: 306520 | Z6: 292103 | AA6: 284429 | AB6: 282943 | AC6: 263414 | AD6: 261590 | AE6: 270369 | AF6: 256935 | AG6: 256601 | AH6: 249370 | AI6: 243604 | AJ6: 234687 | AK6: 234972 | AL6: 229828 | AM6: 232429 | AN6: 225249 | AO6: 227153 | AP6: 219553 | AQ6: 220548 | AR6: 205976 | AS6: 196334 | AT6: 196193 | AU6: 192886 | AV6: 183813 | AW6: 176989 | AX6: 180146 | AY6: 177462 | AZ6: 178860 | BA6: 168283 | BB6: 158847 | BC6: 156102 | BD6: 151005 | BE6: 145123 | BF6: 148408 | BG6: 140949 | BH6: 133301 | BI6: 122071 | BJ6: =VLOOKUP(MID(A6,12,2),'State Codes'!$B$10:$D$60,3,0) -> 9 Pacific | BK6: =VLOOKUP(MID(A6,6,5),'Chart Controls'!$P$3:$Q$8,2,0) -> Electricity
A7: SEDS.ESRCB.CO.A | C7: Billion Btu | E7: EIA, U.S. Energy Information Administration | F7: value | G7: 70607 | H7: 68238 | I7: 70267 | J7: 70373 | K7: 69886 | L7: 66209 | M7: 65807 | N7: 63514 | O7: 64261 | P7: 62729 | Q7: 61733 | R7: 63221 | S7: 62168 | T7: 62360 | U7: 61765 | V7: 59412 | W7: 60462 | X7: 60168 | Y7: 57839 | Z7: 56081 | AA7: 52996 | AB7: 53653 | AC7: 52630 | AD7: 49372 | AE7: 47867 | AF7: 44802 | AG7: 43167 | AH7: 41834 | AI7: 40502 | AJ7: 38578 | AK7: 37323 | AL7: 36357 | AM7: 34856 | AN7: 34459 | AO7: 33394 | AP7: 32740 | AQ7: 32586 | AR7: 31451 | AS7: 30240 | AT7: 30235 | AU7: 29578 | AV7: 32458 | AW7: 30925 | AX7: 28996 | AY7: 22837 | AZ7: 21888 | BA7: 20295 | BB7: 18858 | BC7: 18258 | BD7: 17544 | BE7: 18374 | BF7: 17748 | BG7: 15927 | BH7: 14360 | BI7: 13167 | BJ7: =VLOOKUP(MID(A7,12,2),'State Codes'!$B$10:$D$60,3,0) -> 8 Mountain | BK7: =VLOOKUP(MID(A7,6,5),'Chart Controls'!$P$3:$Q$8,2,0) -> Electricity
A8: SEDS.ESRCB.CT.A | C8: Billion Btu | E8: EIA, U.S. Energy Information Administration | F8: value | G8: 44158 | H8: 42832 | I8: 45007 | J8: 44670 | K8: 44294 | L8: 42628 | M8: 44565 | N8: 42239 | O8: 43254 | P8: 43990 | Q8: 43597 | R8: 44818 | S8: 43529 | T8: 44079 | U8: 44579 | V8: 42917 | W8: 43434 | X8: 45626 | Y8: 44231 | Z8: 47096 | AA8: 45077 | AB8: 44964 | AC8: 42557 | AD8: 40857 | AE8: 39734 | AF8: 39644 | AG8: 37310 | AH8: 37051 | AI8: 37337 | AJ8: 36713 | AK8: 37185 | AL8: 36156 | AM8: 35813 | AN8: 35623 | AO8: 35403 | AP8: 35776 | AQ8: 35145 | AR8: 32994 | AS8: 30982 | AT8: 29474 | AU8: 29290 | AV8: 29913 | AW8: 29020 | AX8: 29391 | AY8: 28040 | AZ8: 27893 | BA8: 27566 | BB8: 27158 | BC8: 26758 | BD8: 25417 | BE8: 25894 | BF8: 26070 | BG8: 24924 | BH8: 23319 | BI8: 21824 | BJ8: =VLOOKUP(MID(A8,12,2),'State Codes'!$B$10:$D$60,3,0) -> 1 New England | BK8: =VLOOKUP(MID(A8,6,5),'Chart Controls'!$P$3:$Q$8,2,0) -> Electricity
A9: SEDS.ESRCB.DE.A | C9: Billion Btu | E9: EIA, U.S. Energy Information Administration | F9: value | G9: 17655 | H9: 16827 | I9: 17777 | J9: 17641 | K9: 17030 | L9: 17074 | M9: 17299 | N9: 15909 | O9: 16252 | P9: 16545 | Q9: 15848 | R9: 15593 | S9: 15428 | T9: 15805 | U9: 16241 | V9: 14791 | W9: 15109 | X9: 15250 | Y9: 14530 | Z9: 15675 | AA9: 14687 | AB9: 14298 | AC9: 13717 | AD9: 12740 | AE9: 12197 | AF9: 12051 | AG9: 11392 | AH9: 11114 | AI9: 11161 | AJ9: 10810 | AK9: 10602 | AL9: 10386 | AM9: 9507 | AN9: 9637 | AO9: 9047 | AP9: 8948 | AQ9: 8643 | AR9: 7947 | AS9: 7237 | AT9: 6565 | AU9: 6495 | AV9: 5274 | AW9: 5003 | AX9: 4925 | AY9: 6367 | AZ9: 6196 | BA9: 6213 | BB9: 6108 | BC9: 5854 | BD9: 5596 | BE9: 4699 | BF9: 4926 | BG9: 4451 | BH9: 4260 | BI9: 3988 | BJ9: =VLOOKUP(MID(A9,12,2),'State Codes'!$B$10:$D$60,3,0) -> 5 South Atlantic | BK9: =VLOOKUP(MID(A9,6,5),'Chart Controls'!$P$3:$Q$8,2,0) -> Electricity
A10: SEDS.ESRCB.DC.A | C10: Billion Btu | E10: EIA, U.S. Energy Information Administration | F10: value | G10: 8345 | H10: 8092 | I10: 8595 | J10: 8626 | K10: 8368 | L10: 8690 | M10: 8845 | N10: 8171 | O10: 8536 | P10: 8522 | Q10: 7070 | R10: 6939 | S10: 6833 | T10: 7033 | U10: 7245 | V10: 6482 | W10: 6536 | X10: 6720 | Y10: 6217 | Z10: 6613 | AA10: 6259 | AB10: 5986 | AC10: 6108 | AD10: 5797 | AE10: 5541 | AF10: 5605 | AG10: 5444 | AH10: 5301 | AI10: 5508 | AJ10: 5488 | AK10: 5362 | AL10: 5578 | AM10: 5077 | AN10: 5391 | AO10: 5051 | AP10: 5002 | AQ10: 5000 | AR10: 4812 | AS10: 4543 | AT10: 4207 | AU10: 4188 | AV10: 4120 | AW10: 3800 | AX10: 3717 | AY10: 3702 | AZ10: 3364 | BA10: 3327 | BB10: 3258 | BC10: 3175 | BD10: 3102 | BE10: 3017 | BF10: 3254 | BG10: 2942 | BH10: 2925 | BI10: 2832 | BJ10: =VLOOKUP(MID(A10,12,2),'State Codes'!$B$10:$D$60,3,0) -> 5 South Atlantic | BK10: =VLOOKUP(MID(A10,6,5),'Chart Controls'!$P$3:$Q$8,2,0) -> Electricity
A11: SEDS.ESRCB.FL.A | C11: Billion Btu | E11: EIA, U.S. Energy Information Administration | F11: value | G11: 472121 | H11: 463367 | I11: 458047 | J11: 444967 | K11: 454816 | L11: 433943 | M11: 428302 | N11: 414430 | O11: 420770 | P11: 418855 | Q11: 397618 | R11: 386559 | S11: 382578 | T11: 396956 | U11: 417099 | V11: 393996 | W11: 388753 | X11: 401989 | Y11: 399385 | Z11: 395080 | AA11: 382837 | AB11: 384361 | AC11: 369055 | AD11: 345899 | AE11: 337807 | AF11: 320203 | AG11: 326761 | AH11: 299728 | AI11: 301330 | AJ11: 292646 | AK11: 274991 | AL11: 262135 | AM11: 249721 | AN11: 248441 | AO11: 242643 | AP11: 232642 | AQ11: 218272 | AR11: 206105 | AS11: 196778 | AT11: 184652 | AU11: 171674 | AV11: 161318 | AW11: 153971 | AX11: 157425 | AY11: 152673 | AZ11: 144048 | BA11: 142782 | BB11: 132914 | BC11: 122907 | BD11: 118588 | BE11: 117186 | BF11: 120232 | BG11: 103875 | BH11: 92893 | BI11: 83969 | BJ11: =VLOOKUP(MID(A11,12,2),'State Codes'!$B$10:$D$60,3,0) -> 5 South Atlantic | BK11: =VLOOKUP(MID(A11,6,5),'Chart Controls'!$P$3:$Q$8,2,0) -> Electricity
A12: SEDS.ESRCB.GA.A | C12: Billion Btu | E12: EIA, U.S. Energy Information Administration | F12: value | G12: 211759 | H12: 199303 | I12: 208611 | J12: 200233 | K12: 198648 | L12: 202439 | M12: 203659 | N12: 186880 | O12: 197519 | P12: 192511 | Q12: 195055 | R12: 182694 | S12: 183088 | T12: 197041 | U12: 210024 | V12: 188198 | W12: 189662 | X12: 191834 | Y12: 186024 | Z12: 180244 | AA12: 174433 | AB12: 164370 | AC12: 165822 | AD12: 151425 | AE12: 152039 | AF12: 142507 | AG12: 141664 | AH12: 125666 | AI12: 128847 | AJ12: 122192 | AK12: 111690 | AL12: 115554 | AM12: 104160 | AN12: 102997 | AO12: 102131 | AP12: 96728 | AQ12: 94203 | AR12: 92093 | AS12: 88056 | AT12: 80198 | AU12: 77010 | AV12: 70719 | AW12: 68742 | AX12: 68947 | AY12: 68353 | AZ12: 62668 | BA12: 65572 | BB12: 63497 | BC12: 57676 | BD12: 56151 | BE12: 51515 | BF12: 52486 | BG12: 47036 | BH12: 44694 | BI12: 42562 | BJ12: =VLOOKUP(MID(A12,12,2),'State Codes'!$B$10:$D$60,3,0) -> 5 South Atlantic | BK12: =VLOOKUP(MID(A12,6,5),'Chart Controls'!$P$3:$Q$8,2,0) -> Electricity
